CUDA 12.8
2025-09-28 22:54:43,938 - INFO - Loading data from noQC/MeanImputedScaledData.csv...
Traceback (most recent call last):
  File "/hpc/group/schultzlab/hs325/miniconda3/envs/gsAI/lib/python3.12/site-packages/pandas/core/indexes/base.py", line 3805, in get_loc
    return self._engine.get_loc(casted_key)
           ^^^^^^^^^^^^^^^^^^^^^^^^^^^^^^^^
  File "index.pyx", line 167, in pandas._libs.index.IndexEngine.get_loc
  File "index.pyx", line 196, in pandas._libs.index.IndexEngine.get_loc
  File "pandas/_libs/hashtable_class_helper.pxi", line 7081, in pandas._libs.hashtable.PyObjectHashTable.get_item
  File "pandas/_libs/hashtable_class_helper.pxi", line 7089, in pandas._libs.hashtable.PyObjectHashTable.get_item
KeyError: 'ID'

The above exception was the direct cause of the following exception:

Traceback (most recent call last):
  File "/work/tfs3/gsAI/02a_10foldcv.py", line 173, in <module>
    main()
  File "/work/tfs3/gsAI/02a_10foldcv.py", line 107, in main
    ids = df["ID"].values
          ~~^^^^^^
  File "/hpc/group/schultzlab/hs325/miniconda3/envs/gsAI/lib/python3.12/site-packages/pandas/core/frame.py", line 4102, in __getitem__
    indexer = self.columns.get_loc(key)
              ^^^^^^^^^^^^^^^^^^^^^^^^^
  File "/hpc/group/schultzlab/hs325/miniconda3/envs/gsAI/lib/python3.12/site-packages/pandas/core/indexes/base.py", line 3812, in get_loc
    raise KeyError(key) from err
KeyError: 'ID'
2025-09-28 22:58:06,467 - INFO - Loading data from noQC/MeanImputedScaledData.csv...
Traceback (most recent call last):
  File "/hpc/group/schultzlab/hs325/miniconda3/envs/gsAI/lib/python3.12/site-packages/pandas/core/indexes/base.py", line 3805, in get_loc
    return self._engine.get_loc(casted_key)
           ^^^^^^^^^^^^^^^^^^^^^^^^^^^^^^^^
  File "index.pyx", line 167, in pandas._libs.index.IndexEngine.get_loc
  File "index.pyx", line 196, in pandas._libs.index.IndexEngine.get_loc
  File "pandas/_libs/hashtable_class_helper.pxi", line 7081, in pandas._libs.hashtable.PyObjectHashTable.get_item
  File "pandas/_libs/hashtable_class_helper.pxi", line 7089, in pandas._libs.hashtable.PyObjectHashTable.get_item
KeyError: 'ID'

The above exception was the direct cause of the following exception:

Traceback (most recent call last):
  File "/work/tfs3/gsAI/02c_10foldcv.py", line 172, in <module>
    main()
  File "/work/tfs3/gsAI/02c_10foldcv.py", line 106, in main
    ids = df["ID"].values
          ~~^^^^^^
  File "/hpc/group/schultzlab/hs325/miniconda3/envs/gsAI/lib/python3.12/site-packages/pandas/core/frame.py", line 4102, in __getitem__
    indexer = self.columns.get_loc(key)
              ^^^^^^^^^^^^^^^^^^^^^^^^^
  File "/hpc/group/schultzlab/hs325/miniconda3/envs/gsAI/lib/python3.12/site-packages/pandas/core/indexes/base.py", line 3812, in get_loc
    raise KeyError(key) from err
KeyError: 'ID'
2025-09-28 23:01:28,202 - INFO - Loading data from noQC/MeanImputedScaledData.csv...
Traceback (most recent call last):
  File "/hpc/group/schultzlab/hs325/miniconda3/envs/gsAI/lib/python3.12/site-packages/pandas/core/indexes/base.py", line 3805, in get_loc
    return self._engine.get_loc(casted_key)
           ^^^^^^^^^^^^^^^^^^^^^^^^^^^^^^^^
  File "index.pyx", line 167, in pandas._libs.index.IndexEngine.get_loc
  File "index.pyx", line 196, in pandas._libs.index.IndexEngine.get_loc
  File "pandas/_libs/hashtable_class_helper.pxi", line 7081, in pandas._libs.hashtable.PyObjectHashTable.get_item
  File "pandas/_libs/hashtable_class_helper.pxi", line 7089, in pandas._libs.hashtable.PyObjectHashTable.get_item
KeyError: 'ID'

The above exception was the direct cause of the following exception:

Traceback (most recent call last):
  File "/work/tfs3/gsAI/02d_10foldcv.py", line 175, in <module>
    main()
  File "/work/tfs3/gsAI/02d_10foldcv.py", line 109, in main
    ids = df["ID"].values
          ~~^^^^^^
  File "/hpc/group/schultzlab/hs325/miniconda3/envs/gsAI/lib/python3.12/site-packages/pandas/core/frame.py", line 4102, in __getitem__
    indexer = self.columns.get_loc(key)
              ^^^^^^^^^^^^^^^^^^^^^^^^^
  File "/hpc/group/schultzlab/hs325/miniconda3/envs/gsAI/lib/python3.12/site-packages/pandas/core/indexes/base.py", line 3812, in get_loc
    raise KeyError(key) from err
KeyError: 'ID'
